Workbook
Name Age_Group: #REF!

Sheet INSTRUCTION
A1: Angler Survey Data Submission Instructions
A2: Please follow these instructions carefully. Changes to the sheet or data guidance will result in a rejection upon submission. Green tabs are to be filled out by the submitter, red tabs are sheet codes and information not to be modified.Explanations for data entry are given in the row header. Ensure that you are using the latest version of the template by checking on the data submission website: https://ffsbcsubmit.azurewebsites.net/
A9: NOTES
A10: 1 | B10: Always start with a blank template
A11: 2 | B11: Sheets are protected to ensure data validation. They can be unprotected and modified but use caution
A12: 3 | B12: BOLD | C12: columns are mandatory. | D12: Not bold | E12: are optional
A13: 4 | B13: Do not add or modify the Codes, Species or Waterbodies tab. These are DB values
A14: 5 | B14: RED | C14: means that you have pasted a value into the cell that violates the data validation rules
A15: 6 | B15: Do not modify the cell data validation constraints. Values that break these constraints will be rejected
A16: 7 | B16: The maximum number of rows per sheet is 2500
A17: 8 | B17: File can be named anything the submitter wants
A18: 9 | B18: Paste only text values. Be careful when pasting values as they can overide allowed drop down values
A19: 10 | B19: To check valid data, use Circle Invalid Data in Data Tools->Data validation (unprotect first)
A20: 11 | B20: Any column that has the calculation format is a calculation cell and is locked | F20: Calculation
A21: 12 | B21: Hover over the column header to get information about the column and its data validation rules
A22: 13 | B22: You can fill in just a party or include individual angler survey question; with an extended survey optional

Sheet SubmissionDetail
A1: Key | B1: Value
A2: template | B2: SURVEY
A3: project_code | B3: FFSBC46_23
A4: source | B4: Mobile Survey
A5: version | B5: 5
A6: comment

Sheet AssessEvent
A1: Existing assess_event_name | B1: waterbody_id | C1: waterbody_name | D1: start_date | E1: end_date | F1: assess_event_name | G1: comment
B2: 00848LNIC | C2: =IF(ISBLANK(B2),"",IF(VLOOKUP(B2,Waterbodies!$A$2:$B$16439,2,FALSE)=0,"",VLOOKUP(B2,Waterbodies!$A$2:$B$16439,2,FALSE))) | D2: 46023 | E2: 46387 | F2: =IF(ISBLANK(A2),IF(OR(ISBLANK(B2),ISBLANK(D2)),"",B2 &"_"&YEAR(D2)& "_" & (VALUE(D2)-VLOOKUP(YEAR(D2),Codes!$A$57:$B$87,2,FALSE)+1)&"_S"),IF(LEN(A2)>80,"",A2))
C3: =IF(ISBLANK(B3),"",IF(VLOOKUP(B3,Waterbodies!$A$2:$B$16439,2,FALSE)=0,"",VLOOKUP(B3,Waterbodies!$A$2:$B$16439,2,FALSE))) | F3: =IF(ISBLANK(A3),IF(OR(ISBLANK(B3),ISBLANK(D3)),"",B3 &"_"&YEAR(D3)& "_" & (VALUE(D3)-VLOOKUP(YEAR(D3),Codes!$A$57:$B$87,2,FALSE)+1)&"_S"),IF(LEN(A3)>80,"",A3))
C4: =IF(ISBLANK(B4),"",IF(VLOOKUP(B4,Waterbodies!$A$2:$B$16439,2,FALSE)=0,"",VLOOKUP(B4,Waterbodies!$A$2:$B$16439,2,FALSE))) | F4: =IF(ISBLANK(A4),IF(OR(ISBLANK(B4),ISBLANK(D4)),"",B4 &"_"&YEAR(D4)& "_" & (VALUE(D4)-VLOOKUP(YEAR(D4),Codes!$A$57:$B$87,2,FALSE)+1)&"_S"),IF(LEN(A4)>80,"",A4))
C5: =IF(ISBLANK(B5),"",IF(VLOOKUP(B5,Waterbodies!$A$2:$B$16439,2,FALSE)=0,"",VLOOKUP(B5,Waterbodies!$A$2:$B$16439,2,FALSE))) | F5: =IF(ISBLANK(A5),IF(OR(ISBLANK(B5),ISBLANK(D5)),"",B5 &"_"&YEAR(D5)& "_" & (VALUE(D5)-VLOOKUP(YEAR(D5),Codes!$A$57:$B$87,2,FALSE)+1)&"_S"),IF(LEN(A5)>80,"",A5))
C6: =IF(ISBLANK(B6),"",IF(VLOOKUP(B6,Waterbodies!$A$2:$B$16439,2,FALSE)=0,"",VLOOKUP(B6,Waterbodies!$A$2:$B$16439,2,FALSE))) | F6: =IF(ISBLANK(A6),IF(OR(ISBLANK(B6),ISBLANK(D6)),"",B6 &"_"&YEAR(D6)& "_" & (VALUE(D6)-VLOOKUP(YEAR(D6),Codes!$A$57:$B$87,2,FALSE)+1)&"_S"),IF(LEN(A6)>80,"",A6))
C7: =IF(ISBLANK(B7),"",IF(VLOOKUP(B7,Waterbodies!$A$2:$B$16439,2,FALSE)=0,"",VLOOKUP(B7,Waterbodies!$A$2:$B$16439,2,FALSE))) | F7: =IF(ISBLANK(A7),IF(OR(ISBLANK(B7),ISBLANK(D7)),"",B7 &"_"&YEAR(D7)& "_" & (VALUE(D7)-VLOOKUP(YEAR(D7),Codes!$A$57:$B$87,2,FALSE)+1)&"_S"),IF(LEN(A7)>80,"",A7))
C8: =IF(ISBLANK(B8),"",IF(VLOOKUP(B8,Waterbodies!$A$2:$B$16439,2,FALSE)=0,"",VLOOKUP(B8,Waterbodies!$A$2:$B$16439,2,FALSE))) | F8: =IF(ISBLANK(A8),IF(OR(ISBLANK(B8),ISBLANK(D8)),"",B8 &"_"&YEAR(D8)& "_" & (VALUE(D8)-VLOOKUP(YEAR(D8),Codes!$A$57:$B$87,2,FALSE)+1)&"_S"),IF(LEN(A8)>80,"",A8))
C9: =IF(ISBLANK(B9),"",IF(VLOOKUP(B9,Waterbodies!$A$2:$B$16439,2,FALSE)=0,"",VLOOKUP(B9,Waterbodies!$A$2:$B$16439,2,FALSE))) | F9: =IF(ISBLANK(A9),IF(OR(ISBLANK(B9),ISBLANK(D9)),"",B9 &"_"&YEAR(D9)& "_" & (VALUE(D9)-VLOOKUP(YEAR(D9),Codes!$A$57:$B$87,2,FALSE)+1)&"_S"),IF(LEN(A9)>80,"",A9))
C10: =IF(ISBLANK(B10),"",IF(VLOOKUP(B10,Waterbodies!$A$2:$B$16439,2,FALSE)=0,"",VLOOKUP(B10,Waterbodies!$A$2:$B$16439,2,FALSE))) | F10: =IF(ISBLANK(A10),IF(OR(ISBLANK(B10),ISBLANK(D10)),"",B10 &"_"&YEAR(D10)& "_" & (VALUE(D10)-VLOOKUP(YEAR(D10),Codes!$A$57:$B$87,2,FALSE)+1)&"_S"),IF(LEN(A10)>80,"",A10))
C11: =IF(ISBLANK(B11),"",IF(VLOOKUP(B11,Waterbodies!$A$2:$B$16439,2,FALSE)=0,"",VLOOKUP(B11,Waterbodies!$A$2:$B$16439,2,FALSE))) | F11: =IF(ISBLANK(A11),IF(OR(ISBLANK(B11),ISBLANK(D11)),"",B11 &"_"&YEAR(D11)& "_" & (VALUE(D11)-VLOOKUP(YEAR(D11),Codes!$A$57:$B$87,2,FALSE)+1)&"_S"),IF(LEN(A11)>80,"",A11))
C12: =IF(ISBLANK(B12),"",IF(VLOOKUP(B12,Waterbodies!$A$2:$B$16439,2,FALSE)=0,"",VLOOKUP(B12,Waterbodies!$A$2:$B$16439,2,FALSE))) | F12: =IF(ISBLANK(A12),IF(OR(ISBLANK(B12),ISBLANK(D12)),"",B12 &"_"&YEAR(D12)& "_" & (VALUE(D12)-VLOOKUP(YEAR(D12),Codes!$A$57:$B$87,2,FALSE)+1)&"_S"),IF(LEN(A12)>80,"",A12))
C13: =IF(ISBLANK(B13),"",IF(VLOOKUP(B13,Waterbodies!$A$2:$B$16439,2,FALSE)=0,"",VLOOKUP(B13,Waterbodies!$A$2:$B$16439,2,FALSE))) | F13: =IF(ISBLANK(A13),IF(OR(ISBLANK(B13),ISBLANK(D13)),"",B13 &"_"&YEAR(D13)& "_" & (VALUE(D13)-VLOOKUP(YEAR(D13),Codes!$A$57:$B$87,2,FALSE)+1)&"_S"),IF(LEN(A13)>80,"",A13))
C14: =IF(ISBLANK(B14),"",IF(VLOOKUP(B14,Waterbodies!$A$2:$B$16439,2,FALSE)=0,"",VLOOKUP(B14,Waterbodies!$A$2:$B$16439,2,FALSE))) | F14: =IF(ISBLANK(A14),IF(OR(ISBLANK(B14),ISBLANK(D14)),"",B14 &"_"&YEAR(D14)& "_" & (VALUE(D14)-VLOOKUP(YEAR(D14),Codes!$A$57:$B$87,2,FALSE)+1)&"_S"),IF(LEN(A14)>80,"",A14))
... C2500: =IF(ISBLANK(B2500),"",IF(VLOOKUP(B2500,Waterbodies!$A$2:$B$16439,2,FALSE)=0,"",VLOOKUP(B2500,Waterbodies!$A$2:$B$16439,2,FALSE))) | F2500: =IF(ISBLANK(A2500),IF(OR(ISBLANK(B2500),ISBLANK(D2500)),"",B2500 &"_"&YEAR(D2500)& "_" & (VALUE(D2500)-VLOOKUP(YEAR(D2500),Codes!$A$57:$B$87,2,FALSE)+1)&"_S"),IF(LEN(A2500)>80,"",A2500))

Sheet Party
A1: assessment_event_name | B1: survey_type | C1: interview_date | D1: party_id | E1: interview_time | F1: trip_complete | G1: location_description | H1: fishing_mode | I1: num_anglers | J1: num_rods | K1: hours_fished | L1: target_species_1 | M1: target_species_2 | N1: angling_method | O1: terminal_gear | P1: comment
A2: 00848LNIC_2026_1_S | B2: CR | C2: 2026-09-04 | D2: 1 | E2: 16:16 | F2: COMPLETE | G2: Mobile_App | H2: SHORE | I2: 1 | J2: 1 | K2: 2 | L2: TR | P2: This is a test response, not actual data
A3: 00848LNIC_2026_1_S | B3: CR | C3: 2026-09-04 | D3: 2 | E3: 16:18 | F3: COMPLETE | G3: Mobile_App | H3: SHORE | I3: 1 | J3: 1 | K3: 2 | L3: TR | P3: Test number two
A4: 00848LNIC_2026_1_S | B4: CR | C4: 2026-09-04 | D4: 3 | E4: 16:19 | F4: COMPLETE | G4: Mobile_App | H4: SHORE | I4: 1 | J4: 1 | K4: 2 | L4: TR | P4: Still trying

Sheet Angler
A1: assessment_event_name | B1: interview_date | C1: party_id | D1: person_id | E1: angling_method | F1: terminal_gear | G1: postal_code_partial | H1: surveyed_this_year_yn | I1: years_fishing | J1: days_fishing_last_2y | K1: days_fishing_this_year | L1: days_ice_last_2y | M1: age | N1: age_group | O1: gender | P1: num_expected_catch | Q1: num_expected_keep | R1: experience_today | S1: licence_code
A2: 00848LNIC_2026_1_S | B2: 2026-09-04 | C2: 1 | D2: 1 | E2: CAST | F2: BAIT-LR | I2: 40
A3: 00848LNIC_2026_1_S | B3: 2026-09-04 | C3: 2 | D3: 1 | E3: CAST | F3: BAIT-LR | I3: 40
A4: 00848LNIC_2026_1_S | B4: 2026-09-04 | C4: 3 | D4: 1 | E4: CAST | F4: BAIT-LR | I4: 40

Sheet Count
A1: assessment_event_name | B1: interview_date | C1: party_id | D1: person_id | E1: species | F1: num_caught | G1: num_kept
A2: 00848LNIC_2026_1_S | B2: 2026-09-04 | C2: 1 | D2: 1 | E2: RB | F2: 1 | G2: 0
A3: 00848LNIC_2026_1_S | B3: 2026-09-04 | C3: 1 | D3: 1 | E3: EB | F3: 4 | G3: 0
A4: 00848LNIC_2026_1_S | B4: 2026-09-04 | C4: 2 | D4: 1 | E4: RB | F4: 1 | G4: 0
A5: 00848LNIC_2026_1_S | B5: 2026-09-04 | C5: 2 | D5: 1 | E5: EB | F5: 4 | G5: 0
A6: 00848LNIC_2026_1_S | B6: 2026-09-04 | C6: 3 | D6: 1 | E6: RB | F6: 1 | G6: 0
A7: 00848LNIC_2026_1_S | B7: 2026-09-04 | C7: 3 | D7: 1 | E7: EB | F7: 4 | G7: 0

Sheet IndividualFish
A1: assessment_event_name | B1: interview_date | C1: party_id | D1: person_id | E1: species | F1: length_mm | G1: weight_g | H1: condition_factor | I1: sex | J1: maturity | K1: sample_collected | L1: fish_vial_id | M1: age_request | N1: mark_code | O1: mark_recap | P1: mark_recap_code | Q1: brood_year | R1: age | S1: stomach_content | T1: stomach_content_additional | U1: angling_method | V1: terminal_gear | W1: terminal_gear_additional | X1: comment
H2: =IF(OR(ISBLANK(F2),ISBLANK(G2)),"",(G2/F2^3*100000)) | R2: =IF(OR(ISBLANK(B2),ISBLANK(E2),ISBLANK(Q2),IF(ISBLANK(E2),TRUE,VLOOKUP(E2,Species!A$2:C$159,3,FALSE)="NA"),Q2>=YEAR(B2)),"",YEAR(B2)-Q2+(IF(VLOOKUP(E2,Species!A$2:C$159,3,FALSE)="SPRING",0,-1)))
H3: =IF(OR(ISBLANK(F3),ISBLANK(G3)),"",(G3/F3^3*100000)) | R3: =IF(OR(ISBLANK(B3),ISBLANK(E3),ISBLANK(Q3),IF(ISBLANK(E3),TRUE,VLOOKUP(E3,Species!A$2:C$159,3,FALSE)="NA"),Q3>=YEAR(B3)),"",YEAR(B3)-Q3+(IF(VLOOKUP(E3,Species!A$2:C$159,3,FALSE)="SPRING",0,-1)))
H4: =IF(OR(ISBLANK(F4),ISBLANK(G4)),"",(G4/F4^3*100000)) | R4: =IF(OR(ISBLANK(B4),ISBLANK(E4),ISBLANK(Q4),IF(ISBLANK(E4),TRUE,VLOOKUP(E4,Species!A$2:C$159,3,FALSE)="NA"),Q4>=YEAR(B4)),"",YEAR(B4)-Q4+(IF(VLOOKUP(E4,Species!A$2:C$159,3,FALSE)="SPRING",0,-1)))
H5: =IF(OR(ISBLANK(F5),ISBLANK(G5)),"",(G5/F5^3*100000)) | R5: =IF(OR(ISBLANK(B5),ISBLANK(E5),ISBLANK(Q5),IF(ISBLANK(E5),TRUE,VLOOKUP(E5,Species!A$2:C$159,3,FALSE)="NA"),Q5>=YEAR(B5)),"",YEAR(B5)-Q5+(IF(VLOOKUP(E5,Species!A$2:C$159,3,FALSE)="SPRING",0,-1)))
H6: =IF(OR(ISBLANK(F6),ISBLANK(G6)),"",(G6/F6^3*100000)) | R6: =IF(OR(ISBLANK(B6),ISBLANK(E6),ISBLANK(Q6),IF(ISBLANK(E6),TRUE,VLOOKUP(E6,Species!A$2:C$159,3,FALSE)="NA"),Q6>=YEAR(B6)),"",YEAR(B6)-Q6+(IF(VLOOKUP(E6,Species!A$2:C$159,3,FALSE)="SPRING",0,-1)))
H7: =IF(OR(ISBLANK(F7),ISBLANK(G7)),"",(G7/F7^3*100000)) | R7: =IF(OR(ISBLANK(B7),ISBLANK(E7),ISBLANK(Q7),IF(ISBLANK(E7),TRUE,VLOOKUP(E7,Species!A$2:C$159,3,FALSE)="NA"),Q7>=YEAR(B7)),"",YEAR(B7)-Q7+(IF(VLOOKUP(E7,Species!A$2:C$159,3,FALSE)="SPRING",0,-1)))
H8: =IF(OR(ISBLANK(F8),ISBLANK(G8)),"",(G8/F8^3*100000)) | R8: =IF(OR(ISBLANK(B8),ISBLANK(E8),ISBLANK(Q8),IF(ISBLANK(E8),TRUE,VLOOKUP(E8,Species!A$2:C$159,3,FALSE)="NA"),Q8>=YEAR(B8)),"",YEAR(B8)-Q8+(IF(VLOOKUP(E8,Species!A$2:C$159,3,FALSE)="SPRING",0,-1)))
H9: =IF(OR(ISBLANK(F9),ISBLANK(G9)),"",(G9/F9^3*100000)) | R9: =IF(OR(ISBLANK(B9),ISBLANK(E9),ISBLANK(Q9),IF(ISBLANK(E9),TRUE,VLOOKUP(E9,Species!A$2:C$159,3,FALSE)="NA"),Q9>=YEAR(B9)),"",YEAR(B9)-Q9+(IF(VLOOKUP(E9,Species!A$2:C$159,3,FALSE)="SPRING",0,-1)))
H10: =IF(OR(ISBLANK(F10),ISBLANK(G10)),"",(G10/F10^3*100000)) | R10: =IF(OR(ISBLANK(B10),ISBLANK(E10),ISBLANK(Q10),IF(ISBLANK(E10),TRUE,VLOOKUP(E10,Species!A$2:C$159,3,FALSE)="NA"),Q10>=YEAR(B10)),"",YEAR(B10)-Q10+(IF(VLOOKUP(E10,Species!A$2:C$159,3,FALSE)="SPRING",0,-1)))
H11: =IF(OR(ISBLANK(F11),ISBLANK(G11)),"",(G11/F11^3*100000)) | R11: =IF(OR(ISBLANK(B11),ISBLANK(E11),ISBLANK(Q11),IF(ISBLANK(E11),TRUE,VLOOKUP(E11,Species!A$2:C$159,3,FALSE)="NA"),Q11>=YEAR(B11)),"",YEAR(B11)-Q11+(IF(VLOOKUP(E11,Species!A$2:C$159,3,FALSE)="SPRING",0,-1)))
H12: =IF(OR(ISBLANK(F12),ISBLANK(G12)),"",(G12/F12^3*100000)) | R12: =IF(OR(ISBLANK(B12),ISBLANK(E12),ISBLANK(Q12),IF(ISBLANK(E12),TRUE,VLOOKUP(E12,Species!A$2:C$159,3,FALSE)="NA"),Q12>=YEAR(B12)),"",YEAR(B12)-Q12+(IF(VLOOKUP(E12,Species!A$2:C$159,3,FALSE)="SPRING",0,-1)))
H13: =IF(OR(ISBLANK(F13),ISBLANK(G13)),"",(G13/F13^3*100000)) | R13: =IF(OR(ISBLANK(B13),ISBLANK(E13),ISBLANK(Q13),IF(ISBLANK(E13),TRUE,VLOOKUP(E13,Species!A$2:C$159,3,FALSE)="NA"),Q13>=YEAR(B13)),"",YEAR(B13)-Q13+(IF(VLOOKUP(E13,Species!A$2:C$159,3,FALSE)="SPRING",0,-1)))
... H2500: =IF(OR(ISBLANK(F2500),ISBLANK(G2500)),"",(G2500/F2500^3*100000)) | R2500: =IF(OR(ISBLANK(B2500),ISBLANK(E2500),ISBLANK(Q2500),IF(ISBLANK(E2500),TRUE,VLOOKUP(E2500,Species!A$2:C$159,3,FALSE)="NA"),Q2500>=YEAR(B2500)),"",YEAR(B2500)-Q2500+(IF(VLOOKUP(E2500,Species!A$2:C$159,3,FALSE)="SPRING",0,-1)))

Sheet ExtendedSurvey
A1: assessment_event_name | B1: interview_date | C1: party_id | D1: person_id | E1: time_travelled | F1: aware_stocking_yn | G1: first_motivation | H1: second_motivation | I1: third_motivation | J1: top_1_waterbody_id | K1: top_1_waterbody_name | L1: top_2_waterbody_id | M1: top_2_waterbody_name | N1: top_3_waterbody_id | O1: top_3_waterbody_name
K2: =IF(ISBLANK(J2),"",IF(VLOOKUP(J2,Waterbodies!$A$2:$B$16439,2,FALSE)=0,"",VLOOKUP(J2,Waterbodies!$A$2:$B$16439,2,FALSE))) | M2: =IF(ISBLANK(L2),"",IF(VLOOKUP(L2,Waterbodies!$A$2:$B$16439,2,FALSE)=0,"",VLOOKUP(L2,Waterbodies!$A$2:$B$16439,2,FALSE))) | O2: =IF(ISBLANK(N2),"",IF(VLOOKUP(N2,Waterbodies!$A$2:$B$16439,2,FALSE)=0,"",VLOOKUP(N2,Waterbodies!$A$2:$B$16439,2,FALSE)))
K3: =IF(ISBLANK(J3),"",IF(VLOOKUP(J3,Waterbodies!$A$2:$B$16439,2,FALSE)=0,"",VLOOKUP(J3,Waterbodies!$A$2:$B$16439,2,FALSE))) | M3: =IF(ISBLANK(L3),"",IF(VLOOKUP(L3,Waterbodies!$A$2:$B$16439,2,FALSE)=0,"",VLOOKUP(L3,Waterbodies!$A$2:$B$16439,2,FALSE))) | O3: =IF(ISBLANK(N3),"",IF(VLOOKUP(N3,Waterbodies!$A$2:$B$16439,2,FALSE)=0,"",VLOOKUP(N3,Waterbodies!$A$2:$B$16439,2,FALSE)))
K4: =IF(ISBLANK(J4),"",IF(VLOOKUP(J4,Waterbodies!$A$2:$B$16439,2,FALSE)=0,"",VLOOKUP(J4,Waterbodies!$A$2:$B$16439,2,FALSE))) | M4: =IF(ISBLANK(L4),"",IF(VLOOKUP(L4,Waterbodies!$A$2:$B$16439,2,FALSE)=0,"",VLOOKUP(L4,Waterbodies!$A$2:$B$16439,2,FALSE))) | O4: =IF(ISBLANK(N4),"",IF(VLOOKUP(N4,Waterbodies!$A$2:$B$16439,2,FALSE)=0,"",VLOOKUP(N4,Waterbodies!$A$2:$B$16439,2,FALSE)))
K5: =IF(ISBLANK(J5),"",IF(VLOOKUP(J5,Waterbodies!$A$2:$B$16439,2,FALSE)=0,"",VLOOKUP(J5,Waterbodies!$A$2:$B$16439,2,FALSE))) | M5: =IF(ISBLANK(L5),"",IF(VLOOKUP(L5,Waterbodies!$A$2:$B$16439,2,FALSE)=0,"",VLOOKUP(L5,Waterbodies!$A$2:$B$16439,2,FALSE))) | O5: =IF(ISBLANK(N5),"",IF(VLOOKUP(N5,Waterbodies!$A$2:$B$16439,2,FALSE)=0,"",VLOOKUP(N5,Waterbodies!$A$2:$B$16439,2,FALSE)))
K6: =IF(ISBLANK(J6),"",IF(VLOOKUP(J6,Waterbodies!$A$2:$B$16439,2,FALSE)=0,"",VLOOKUP(J6,Waterbodies!$A$2:$B$16439,2,FALSE))) | M6: =IF(ISBLANK(L6),"",IF(VLOOKUP(L6,Waterbodies!$A$2:$B$16439,2,FALSE)=0,"",VLOOKUP(L6,Waterbodies!$A$2:$B$16439,2,FALSE))) | O6: =IF(ISBLANK(N6),"",IF(VLOOKUP(N6,Waterbodies!$A$2:$B$16439,2,FALSE)=0,"",VLOOKUP(N6,Waterbodies!$A$2:$B$16439,2,FALSE)))
K7: =IF(ISBLANK(J7),"",IF(VLOOKUP(J7,Waterbodies!$A$2:$B$16439,2,FALSE)=0,"",VLOOKUP(J7,Waterbodies!$A$2:$B$16439,2,FALSE))) | M7: =IF(ISBLANK(L7),"",IF(VLOOKUP(L7,Waterbodies!$A$2:$B$16439,2,FALSE)=0,"",VLOOKUP(L7,Waterbodies!$A$2:$B$16439,2,FALSE))) | O7: =IF(ISBLANK(N7),"",IF(VLOOKUP(N7,Waterbodies!$A$2:$B$16439,2,FALSE)=0,"",VLOOKUP(N7,Waterbodies!$A$2:$B$16439,2,FALSE)))
K8: =IF(ISBLANK(J8),"",IF(VLOOKUP(J8,Waterbodies!$A$2:$B$16439,2,FALSE)=0,"",VLOOKUP(J8,Waterbodies!$A$2:$B$16439,2,FALSE))) | M8: =IF(ISBLANK(L8),"",IF(VLOOKUP(L8,Waterbodies!$A$2:$B$16439,2,FALSE)=0,"",VLOOKUP(L8,Waterbodies!$A$2:$B$16439,2,FALSE))) | O8: =IF(ISBLANK(N8),"",IF(VLOOKUP(N8,Waterbodies!$A$2:$B$16439,2,FALSE)=0,"",VLOOKUP(N8,Waterbodies!$A$2:$B$16439,2,FALSE)))
K9: =IF(ISBLANK(J9),"",IF(VLOOKUP(J9,Waterbodies!$A$2:$B$16439,2,FALSE)=0,"",VLOOKUP(J9,Waterbodies!$A$2:$B$16439,2,FALSE))) | M9: =IF(ISBLANK(L9),"",IF(VLOOKUP(L9,Waterbodies!$A$2:$B$16439,2,FALSE)=0,"",VLOOKUP(L9,Waterbodies!$A$2:$B$16439,2,FALSE))) | O9: =IF(ISBLANK(N9),"",IF(VLOOKUP(N9,Waterbodies!$A$2:$B$16439,2,FALSE)=0,"",VLOOKUP(N9,Waterbodies!$A$2:$B$16439,2,FALSE)))
K10: =IF(ISBLANK(J10),"",IF(VLOOKUP(J10,Waterbodies!$A$2:$B$16439,2,FALSE)=0,"",VLOOKUP(J10,Waterbodies!$A$2:$B$16439,2,FALSE))) | M10: =IF(ISBLANK(L10),"",IF(VLOOKUP(L10,Waterbodies!$A$2:$B$16439,2,FALSE)=0,"",VLOOKUP(L10,Waterbodies!$A$2:$B$16439,2,FALSE))) | O10: =IF(ISBLANK(N10),"",IF(VLOOKUP(N10,Waterbodies!$A$2:$B$16439,2,FALSE)=0,"",VLOOKUP(N10,Waterbodies!$A$2:$B$16439,2,FALSE)))
K11: =IF(ISBLANK(J11),"",IF(VLOOKUP(J11,Waterbodies!$A$2:$B$16439,2,FALSE)=0,"",VLOOKUP(J11,Waterbodies!$A$2:$B$16439,2,FALSE))) | M11: =IF(ISBLANK(L11),"",IF(VLOOKUP(L11,Waterbodies!$A$2:$B$16439,2,FALSE)=0,"",VLOOKUP(L11,Waterbodies!$A$2:$B$16439,2,FALSE))) | O11: =IF(ISBLANK(N11),"",IF(VLOOKUP(N11,Waterbodies!$A$2:$B$16439,2,FALSE)=0,"",VLOOKUP(N11,Waterbodies!$A$2:$B$16439,2,FALSE)))
K12: =IF(ISBLANK(J12),"",IF(VLOOKUP(J12,Waterbodies!$A$2:$B$16439,2,FALSE)=0,"",VLOOKUP(J12,Waterbodies!$A$2:$B$16439,2,FALSE))) | M12: =IF(ISBLANK(L12),"",IF(VLOOKUP(L12,Waterbodies!$A$2:$B$16439,2,FALSE)=0,"",VLOOKUP(L12,Waterbodies!$A$2:$B$16439,2,FALSE))) | O12: =IF(ISBLANK(N12),"",IF(VLOOKUP(N12,Waterbodies!$A$2:$B$16439,2,FALSE)=0,"",VLOOKUP(N12,Waterbodies!$A$2:$B$16439,2,FALSE)))
K13: =IF(ISBLANK(J13),"",IF(VLOOKUP(J13,Waterbodies!$A$2:$B$16439,2,FALSE)=0,"",VLOOKUP(J13,Waterbodies!$A$2:$B$16439,2,FALSE))) | M13: =IF(ISBLANK(L13),"",IF(VLOOKUP(L13,Waterbodies!$A$2:$B$16439,2,FALSE)=0,"",VLOOKUP(L13,Waterbodies!$A$2:$B$16439,2,FALSE))) | O13: =IF(ISBLANK(N13),"",IF(VLOOKUP(N13,Waterbodies!$A$2:$B$16439,2,FALSE)=0,"",VLOOKUP(N13,Waterbodies!$A$2:$B$16439,2,FALSE)))
... K2500: =IF(ISBLANK(J2500),"",IF(VLOOKUP(J2500,Waterbodies!$A$2:$B$16439,2,FALSE)=0,"",VLOOKUP(J2500,Waterbodies!$A$2:$B$16439,2,FALSE))) | M2500: =IF(ISBLANK(L2500),"",IF(VLOOKUP(L2500,Waterbodies!$A$2:$B$16439,2,FALSE)=0,"",VLOOKUP(L2500,Waterbodies!$A$2:$B$16439,2,FALSE))) | O2500: =IF(ISBLANK(N2500),"",IF(VLOOKUP(N2500,Waterbodies!$A$2:$B$16439,2,FALSE)=0,"",VLOOKUP(N2500,Waterbodies!$A$2:$B$16439,2,FALSE)))

Sheet Codes
A1: Method | B1: Description | D1: Gender | E1: Description | G1: MarkCode | H1: Description | J1: Sex | K1: Description
A2: AN | B2: Interview conducted while angling | D2: M | E2: Male | G2: AD | H2: Adipose | J2: F | K2: Female
A3: CR | B3: Creel interview (boat or ramp) | D3: F | E3: Female | G3: ALM | H3: Adipose & Left Maxillary | J3: I | K3: Intersex
A4: DB | B4: Interview at a derby | D4: NB | E4: Non-binary | G4: ALMLV | H4: Adipose & Left Maxillary & Left Ventral | J4: M | K4: Male
A5: COS | B5: Conservation Officer Survey | D5: RF | E5: Refused | G5: ALMRV | H5: Adipose & Left Maxillary & Right Ventral | J5: U | K5: Unknown
G6: ALP | H6: Adipose & Left Pelvic | J6: Maturity | K6: Description
A7: FishingMode | B7: Description | D7: YesNoMaybe | G7: ALV | H7: Adipose & Left Ventral | J7: UNK | K7: Unknown
A8: BOAT | B8: Any multiple person vessel | D8: YES | G8: ALVRV | H8: Adipose & Right Ventral & Left Ventral | J8: ST | K8: Spent
A9: SPV | B9: Single person vessel (belly boat, etc.) | D9: NO | G9: AOP | H9: Adipose & Operculum Punch | J9: SP | K9: Spawning
A10: ICE | B10: Ice fishing | D10: MAYBE | G10: ARLV | H10: Adipose & Right and Left Ventral | J10: SB | K10: Spawn Bound
A11: SHORE | B11: Fishing from shore | G11: ARM | H11: Adipose & Right Maxillary | J11: R | K11: Resting
D12: Binary | G12: ARMLM | H12: Adipose & Right Max & Left Maxillary | J12: MT | K12: Maturing
A13: AgeGroup | B13: Description | D13: YES | G13: ARMLV | H13: Adipose & Right Maxillary & Left Ventral | J13: MR | K13: Mature - Repeat Spawner
A14: <16 | B14: Less than 16 | D14: NO | G14: ARMRV | H14: Adipose & Left Maxillary & Right Ventral | J14: M | K14: Mature
A15: 16-24 | B15: Between 16 and 24 | G15: ARV | H15: Adipose & Right Ventral | J15: IM | K15: Immature
A16: 25-34 | B16: Between 25 and 34 | G16: CC | H16: Center caudal punch or clip
A17: 35-44 | B17: Between 35 and 44 | D17: AnglingMethodCode | E17: Description | G17: CLC | H17: Center & Lower caudal punch or clip | J17: StomachContent | K17: Description
A18: 45-54 | B18: Between 45 and 54 | D18: CAST | E18: Casting | G18: CLUC | H18: Center,Lower,Upper caudal punch or clip | J18: ANTS | K18: Ants
A19: 55-64 | B19: Between 55 and 64 | D19: TROLL | E19: Trolling | G19: CUC | H19: Center & Upper caudal punch or clip | J19: BEET | K19: Beetles
A20: 65+ | B20: 65 or older | D20: ICE | E20: Ice fishing | G20: CWT | H20: Coded Wire Tag & Adipose | J20: CFL | K20: Caddis Fly Larvea
A21: REFUSED | B21: Refused to answer | D21: MIX | E21: Casting & Trolling | G21: CWTALM | H21: Coded Wire Tag & Adipose & L-Maxillary | J21: CHAO | K21: Chaoboridae
G22: CWTALV | H22: Coded Wire Tag & Adipose & Left Ventral | J22: CHIR | K22: Chironomidae
A23: Motivation | B23: Description | D23: TerminalGearCode | E23: Description | G23: CWTARM | H23: Coded Wire Tag & Adipose & R-Maxillary | J23: CORIX | K23: Boatman or Backswimmer
A24: AWAY | B24: To get away | D24: FLY | E24: Artificial fly (dry, wet, leech, etc.) | G24: CWTARV | H24: Coded Wire Tag & Adipose & Right Ventral | J24: DMN | K24: Damselfly nymph
A25: CHALLENGE | B25: Catch a challenging fish | D25: LURE | E25: Lure (spoon, plug, spinner, etc.) | G25: CWTLM | H25: Coded Wire Tag & Left Maxillary | J25: DRFL | K25: Dragon Fly
A26: COMPANION | B26: For companionship | D26: BAIT | E26: Bait (roe, worms, maggots, etc.) | G26: CWTLV | H26: Coded Wire Tag & Left Ventral | J26: EMPTY | K26: Empty
A27: EATING | B27: Catch fish for eating | D27: FLY-LURE | E27: FLY & LURE different rods or switching | G27: CWTRM | H27: Coded Wire Tag & Right Maxillary | J27: FISH | K27: Fish
A28: FAMILY | B28: To be with family closer together | D28: BAIT-FLY | E28: BAIT & FLY different rods or switching | G28: CWTRV | H28: Coded Wire Tag & Right Ventral | J28: GAM | K28: Gamarus shrimp
A29: LARGE | B29: Catch a large fish | D29: BAIT-LR | E29: BAIT & LURE different rods or switching | G29: FG | H29: Florescent Grit | J29: HYAL | K29: Hyallella shrimp
A30: MANY | B30: Catch many fish | G30: FGDG | H30: Florescent Grit Dark Green | J30: LEECH | K30: Leeches
A31: NATURE | B31: Close to nature | D31: SampleCollected | E31: Description | G31: FGG | H31: Florescent Grit Green | J31: MOL | K31: Snails, clams, etc
A32: RELAX | B32: To relax | D32: OT | E32: Otolith only | G32: FGGAD | H32: Florescent Grit Green & Adipose | J32: MYSIS | K32: Mysis shrimp
A33: SKILLS | B33: To improve skills | D33: SC | E33: Scale only | G33: FGLG | H33: Florescent Grit Light Green | J33: PLANK | K33: Plankton
D34: OT-SC | E34: Otolith & scale | G34: FGO | H34: Florescent Grit Orange | J34: TERR | K34: Terrestrial flying insect (bees, moths)
A35: LicenseType | D35: DNA | E35: DNA only | G35: FGORM | H35: Florescent Grit Orange & Right Maxillary | J35: UNK | K35: Unknown
A36: 1DAY | B36: 1 Day | D36: DNA-OT | E36: DNA & otolith | G36: FGR | H36: Florescent Grit Red | J36: BLACK | K36: Blackspot disease
A37: 8DAY | B37: 8 Day | D37: DNA-SC | E37: DNA & scale | G37: FGRO | H37: Florescent Grit Red/Orange | J37: TAPE | K37: Tapeworm
A38: ANN65+ | B38: Annual 65+ | D38: DNA-OT-SC | E38: DNA & otolith & scale | G38: FGRRV | H38: Florescent Grit Red & Right Ventral | J38: INVERT | K38: Invertebrates
A39: ANNUAL | B39: Annual | G39: FLOY | H39: Floy tag (spaghetti tag)
A40: DISABLED | B40: Annual Disabled | D40: SurveyConductedAs | E40: Description | G40: LC | H40: Lower Caudal
...

Sheet Species
A1: species_code | B1: common_name | C1: spawn_season_code
A2: ABT | B2: Anadromous Bull Trout | C2: FALL
A3: AC | B3: Arctic Char | C3: FALL
A4: ACT | B4: Coastal Cutthroat (anadromous) | C4: SPRING
A5: ADV | B5: Anadromous Dolly Varden | C5: FALL
A6: AEB | B6: Anadromous Eastern Brook Trout | C6: FALL
A7: AGB | B7: Anadromous Brown Trout | C7: FALL
A8: AL | B8: Arctic Lamprey | C8: NA
A9: AS | B9: Atlantic Salmon | C9: FALL
A10: BB | B10: Burbot | C10: WI
A11: BCB | B11: Black Crappie | C11: SPRING
A12: BH | B12: Catfish | C12: SPRING
... A158: YB | B158: Yellow Bullhead | C158: SPRING

Sheet Waterbodies
A1: waterbody_code | B1: locale_name | C1: waterbody_type
A2: 00000PARK | B2: FORD CREEK | C2: MM
A3: 00001BRID | B3: BOBBS | C3: LK
A4: 00001CHIL | B4: TASA | C4: LK
A5: 00001CHWK | B5: LING | C5: LK
A6: 00001ELKR | B6: FOX | C6: LK
A7: 00001LNIC | B7: FRED | C7: LK
A8: 00001LNRS | B8: NATALKUZ | C8: LK
A9: 00001PARA | B9: WILLISTON | C9: LK
A10: 00001PARS | B10: AZOUZETTA | C10: LK
A11: 00001QUES | B11: TEN MILE | C11: LK
A12: 00001SLOC | B12: ROSEBERY (PARK) | C12: LK
... A5803: TMPWBID07 | B5803: IONA PIT | C5803: MM
A5804: 00001LARL | C5804: LK
A5805: 00001LCHR | C5805: LK
A5806: 00001NIMP | C5806: LK
A5807: 00001SMAR | C5807: LK
A5808: 00001UNTH | C5808: LK
A5809: 00002BULL | C5809: LK
A5810: 00002CHIL | C5810: LK
A5811: 00002JERV | C5811: LK
A5812: 00003BULL | C5812: LK
A5813: 00003JERV | C5813: LK
A5814: 00003NIMP | C5814: LK
A5815: 00003SMAR | C5815: LK
... A16439: 73000BULK | C16439: LK

Sheet Projects
A1: project_code | B1: project_name | C1: comment
A2: S2107 | B2: R4 Small Lake Assessments | C2: $4800 Aging lab allocation
A3: S2113 | B3: R7A Small Lakes Stock Assessments | C3: $5280 Aging lab allocation
A4: S2208 | B4: FLIGHTLINES - Williams Lake/100 Mile | C4: 100 Mile/Williams Lake Flightline
A5: S2213 | B5: R7B Small Lakes Assessments (4 lakes) | C5: 1440 for BCPAL
A6: S2011 | B6: R5 Small Lake Assessments | C6: 2019 Small Lakes Assessments in Region 5
A7: S2202 | B7: R1 SLA (15 lakes) | C7: 2389 for BCPAL
A8: S2211 | B8: R7a SLA (10 lakes) | C8: SLA (10 lakes) - Region 7a Small Lakes Assessments. 4320 for BCPAL
A9: S2106 | B9: R3 Flight Lines | C9: Aerial assessment of angler effort on small lakes in Region 3.
A10: S1709 | B10: R5 Aerial Effort – Williams Lake Quesnel | C10: Aerial Effort survey of small lakes in the Williams Lake/Quesnel Areas
A11: S1810 | B11: R4 Effort Counts | C11: Alces and Premier Lake Effort Counts
A12: FFSBC40_15 | B12: Horsefly Exploratory | C12: Previously S1612, now all HF lakes assessments of all methods are here.
... A85: S1901 | B85: R2 SLA Nutrient Enhancement Exploration | C85: WQ, primary productivity and stock assessment of each lake, consideration of lake suitability for potential future nutrient enhancement.
A86: FFSBC1_0509 | B86: EBT Study
A87: FFSBC22_0913 | B87: Analysis of catchability in RBT strains
A88: FFSBC26_09 | B88: Blackwater Comparison
A89: FFSBC27_05 | B89: Blackwater AF, AF3n Comparison | C89: Duplication of FFSBC26_09?
A90: FFSBC28_0408 | B90: Moss lakes Project
A91: FFSBC29_09 | B91: KO Effort
A92: FFSBC30_10 | B92: Fish Lake (Taseko)
A93: FFSBC34_12_pH | B93: pH Brood Development
A94: FFSBC35_12 | B94: KO AF3n assessment
A95: FFSBC41_1214 | B95: Copper Wool EBT Assessments
A96: FFSBC5_0000 | B96: Brood Lake Assessment: Tunkwa lake
A97: FFSBC7_0710 | B97: AF3n development
A98: FFSBC8_0609 | B98: KO 3n assessment
A99: UL | B99: Urban Lakes Project
A100: SLIM | B100: SLIM counts from pre-2010
A101: S1615 | B101: R4 Small Lake Assessments 2015
... A121: S1806 | B121: R7A Camera-based Effort Assessment
A122: S2207 | B122: R4 Small Lake Creel Surveys | C122: Alces
A123: S1505 | B123: R8 Flightline SW Transect Effort Count
A124: S2201 | B124: R1 Small Lakes Fertilization
A125: S2301 | B125: R3 Small Lakes Assessments
A126: S2303 | B126: R1 Small Lakes Assessments
A127: S2304 | B127: R4 Aerial Angler Survey (Upper Columbia)
A128: S2305 | B128: R4 Small Lakes Assessments
A129: S2306 | B129: R8 FLIGHTLINE
A130: S2307 | B130: R2 Priority Lake Stock Assessment
A131: S2308 | B131: R8 Small Lakes Assessment
...
